Workbook
Name _1нед: [1]!Таблица1[оценказа1неделю]
Name _2нед: [1]!Таблица1[оценказа2неделю]
Name _3нед: [1]!Таблица1[оценказа3неделю]
Name _4нед: [1]!Таблица1[оценказа4неделю]

Sheet Лист4
A3: Пол | B3: Ранееобучался | C3: Количество по полю ID | D3: Среднее по полю Оценказа1неделю | E3: Среднее по полю Оценказа2неделю | F3: Среднее по полю Оценказа3неделю | G3: Среднее по полю Оценказа4неделю | H3: Среднее по полю средняя за 5 недели
A4: Ж | B4: Да | C4: 30 | D4: 3.4333333 | E4: 3.5 | F4: 3.6 | G4: 3.9 | H4: 3.5666667
B5: Нет | C5: 43 | D5: 3.4418605 | E5: 3.4186047 | F5: 3.372093 | G5: 3.9767442 | H5: 3.5302326
A6: М | B6: Да | C6: 45 | D6: 3.6444444 | E6: 3.6666667 | F6: 3.7555556 | G6: 3.5333333 | H6: 3.6533333
B7: Нет | C7: 27 | D7: 3.8148148 | E7: 3.5185185 | F7: 3.6296296 | G7: 3.5555556 | H7: 3.637037
A8: Общий итог | C8: 145 | D8: 3.5724138 | E8: 3.5310345 | F8: 3.5862069 | G8: 3.7448276 | H8: 3.5958621
A12: Названия строк | B12: Количество по полю ID | C12: Сумма по полю ID
A13: Ж | B13: 73 | C13: 0.50343664
A14: М | B14: 72 | C14: 0.49656336
A15: Общий итог | B15: 145 | C15: 1

Sheet Успеваемость
B2: ID | C2: Студент | D2: Датарождения | E2: Пол | F2: Ранееобучался | G2: Оценказа1неделю | H2: Оценказа2неделю | I2: Оценказа3неделю | J2: Оценказа4неделю | K2: Оценказа5неделю | L2: средняя за 5 недели | M2: категория | N2: разница между 5 и 1 неделей | O2: успеваемость стала | S2: категория
B3: 12991 | C3: Аида Нургалиева | D3: 02.01.1979 | E3: Ж | F3: Нет | G3: 4 | H3: 4 | I3: 4 | J3: 4 | K3: 5 | L3: 4.2 | M3: Хорошо | N3: 1 | O3: лучше | S3: 2 | T3: не очень
B4: 13014 | C4: Айгерім Нұрланқызы | D4: 09.04.1997 | E4: Ж | F4: Нет | G4: 3 | H4: 2 | I4: 5 | J4: 5 | K4: 4 | L4: 3.8 | M4: Нормольно | N4: 1 | O4: лучше | S4: 3 | T4: Нормольно
B5: 13002 | C5: Айгуль Нурмухамедова | D5: 30.07.1997 | E5: Ж | F5: Нет | G5: 4 | H5: 3 | I5: 4 | J5: 4 | K5: 3 | L5: 3.6 | M5: Нормольно | N5: -1 | O5: хуже | S5: 4 | T5: Хорошо
B6: 13003 | C6: Айдана Жұмабекқызы | D6: 10.05.1984 | E6: Ж | F6: Да | G6: 3 | H6: 4 | I6: 3 | J6: 2 | K6: 5 | L6: 3.4 | M6: Нормольно | N6: 2 | O6: лучше | S6: 5 | T6: Отлично
B7: 12987 | C7: Айдана Токаева | D7: 13.12.1995 | E7: Ж | F7: Нет | G7: 4 | H7: 5 | I7: 2 | J7: 2 | K7: 3 | L7: 3.2 | M7: Нормольно | N7: -1 | O7: хуже
B8: 12977 | C8: Айдана Токаева | D8: 13.12.1995 | E8: Ж | F8: Нет | G8: 2 | H8: 3 | I8: 3 | J8: 5 | K8: 2 | L8: 3 | M8: Нормольно | N8: 0 | O8: хуже
B9: 13023 | C9: Айнара Қайратқызы | D9: 04.08.1999 | E9: Ж | F9: Да | G9: 5 | H9: 5 | I9: 5 | J9: 5 | K9: 4 | L9: 4.8 | M9: Хорошо | N9: -1 | O9: хуже
B10: 12979 | C10: Алия Садыкова | D10: 28.08.1992 | E10: Ж | F10: Нет | G10: 4 | H10: 5 | I10: 4 | J10: 3 | K10: 3 | L10: 3.8 | M10: Нормольно | N10: -1 | O10: хуже
B11: 12994 | C11: Алма Керимбаева | D11: 23.10.1976 | E11: Ж | F11: Нет | G11: 3 | H11: 2 | I11: 3 | J11: 4 | K11: 3 | L11: 3 | M11: Нормольно | N11: 0 | O11: хуже
B12: 13017 | C12: Алтынай Зұлпықарқызы | D12: 15.11.1981 | E12: Ж | F12: Да | G12: 5 | H12: 3 | I12: 4 | J12: 3 | K12: 3 | L12: 3.6 | M12: Нормольно | N12: -2 | O12: хуже
B13: 13000 | C13: Альфия Ибрагимова | D13: 06.08.1978 | E13: Ж | F13: Нет | G13: 4 | H13: 4 | I13: 2 | J13: 4 | K13: 3 | L13: 3.4 | M13: Нормольно | N13: -1 | O13: хуже
B14: 13032 | C14: Арман Қуандықұлы | D14: 21.06.1998 | E14: М | F14: Нет | G14: 3 | H14: 4 | I14: 4 | J14: 5 | K14: 5 | L14: 4.2 | M14: Хорошо | N14: 2 | O14: лучше
B15: 12998 | C15: Аружан Таибаева | D15: 01.11.2000 | E15: Ж | F15: Нет | G15: 4 | H15: 5 | I15: 3 | J15: 3 | K15: 3 | L15: 3.6 | M15: Нормольно | N15: -1 | O15: хуже
B16: 12971 | C16: Асылзат Мусина | D16: 22.03.1980 | E16: Ж | F16: Да | G16: 3 | H16: 4 | I16: 3 | J16: 5 | K16: 2 | L16: 3.4 | M16: Нормольно | N16: -1 | O16: хуже
B17: 13001 | C17: Бауыржан Мусабеков | D17: 09.02.1983 | E17: М | F17: Да | G17: 2 | H17: 2 | I17: 3 | J17: 5 | K17: 4 | L17: 3.2 | M17: Нормольно | N17: 2 | O17: лучше
B18: 12986 | C18: Бекзат Исакулов | D18: 20.09.1983 | E18: М | F18: Да | G18: 4 | H18: 4 | I18: 5 | J18: 3 | K18: 2 | L18: 3.6 | M18: Нормольно | N18: -2 | O18: хуже
... B67: 13063 | C67: Айбек Нұрланов | D67: 4,4.хуже. | E67: М | F67: Нет | G67: 5 | H67: 5 | I67: 3 | J67: 5 | K67: 4 | L67: 4.4 | M67: Хорошо | N67: -1 | O67: хуже
B68: 13101 | C68: Айгерим Турганбаева | D68: 36048 | E68: Ж | F68: Нет | G68: 5 | H68: 4 | I68: 4 | J68: 5 | K68: 5 | L68: 4.6 | M68: Хорошо | N68: 0 | O68: хуже
B69: 13111 | C69: Айгерим Турганбаева | D69: 07.02.1999 | E69: М | F69: Нет | G69: 3 | H69: 2 | I69: 3 | J69: 4 | K69: 5 | L69: 3.4 | M69: Нормольно | N69: 2 | O69: лучше
B70: 13094 | C70: Айгерім Жақыпова | D70: 18.07.1992 | E70: М | F70: Да | G70: 5 | H70: 5 | I70: 3 | J70: 3 | K70: 4 | L70: 4 | M70: Хорошо | N70: -1 | O70: хуже
B71: 13036 | C71: Айгүл Мейірбекқызы | D71: 19.03.1996 | E71: Ж | F71: Нет | G71: 3 | H71: 2 | I71: 1 | J71: 4 | K71: 4 | L71: 2.8 | M71: не очень | N71: 1 | O71: лучше
B72: 13052 | C72: Айзере Болатқызы | D72: 20.07.1999 | E72: Ж | F72: Нет | G72: 5 | H72: 2 | I72: 3 | J72: 4 | K72: 4 | L72: 3.6 | M72: Нормольно | N72: -1 | O72: хуже
B73: 13107 | C73: Айзере Толепбергенова | D73: 35555 | E73: Ж | F73: Нет | G73: 2 | H73: 2 | I73: 3 | J73: 3 | K73: 5 | L73: 3 | M73: Нормольно | N73: 3 | O73: лучше
B74: 13078 | C74: Айым Серікқызы | D74: 14.08.1985 | E74: М | F74: Да | G74: 2 | H74: 2 | I74: 5 | J74: 4 | K74: 2 | L74: 3 | M74: Нормольно | N74: 0 | O74: хуже
B75: 13088 | C75: Ақбота Жанәбілова | D75: 13.03.1993 | E75: Ж | F75: Нет | G75: 5 | H75: 2 | I75: 4 | J75: 2 | K75: 4 | L75: 3.4 | M75: Нормольно | N75: -1 | O75: хуже
B76: 13046 | C76: Ақерке Асылбекқызы | D76: 05.05.1987 | E76: Ж | F76: Нет | G76: 3 | H76: 4 | I76: 1 | J76: 5 | K76: 2 | L76: 3 | M76: Нормольно | N76: -1 | O76: хуже
B77: 13074 | C77: Алина Жақсылықова | D77: 20.08.2009 | E77: Ж | F77: Нет | G77: 3 | H77: 2 | I77: 4 | J77: 3 | K77: 4 | L77: 3.2 | M77: Нормольно | N77: 1 | O77: лучше
B78: 13053 | C78: Алина Сағатқызы | D78: 12.06.1984 | E78: Ж | F78: Да | G78: 2 | H78: 3 | I78: 4 | J78: 3 | K78: 3 | L78: 3 | M78: Нормольно | N78: 1 | O78: лучше
B79: 13056 | C79: Алма Бауыржанқызы | D79: 16.09.1992 | E79: Ж | F79: Нет | G79: 3 | H79: 5 | I79: 1 | J79: 4 | K79: 2 | L79: 3 | M79: Нормольно | N79: -1 | O79: хуже
B80: 13073 | C80: Арман Тұрсынов | D80: 15.05.2005 | E80: М | F80: Нет | G80: 5 | H80: 2 | I80: 4 | J80: 2 | K80: 2 | L80: 3 | M80: Нормольно | N80: -3 | O80: хуже
B81: 13099 | C81: Арсен Нұрғалиев | D81: 5.08.2007 | E81: Ж | F81: Нет | G81: 2 | H81: 2 | I81: 2 | J81: 4 | K81: 5 | L81: 3 | M81: Нормольно | N81: 3 | O81: лучше
B82: 13080 | C82: Аружан Қанатова | D82: 23.05.1985 | E82: Ж | F82: Да | G82: 5 | H82: 4 | I82: 5 | J82: 4 | K82: 5 | L82: 4.6 | M82: Хорошо | N82: 0 | O82: хуже
B83: 13066 | C83: Аружан Төлегенова | D83: 12.02.2003 | E83: Ж | F83: Да | G83: 2 | H83: 2 | I83: 4 | J83: 5 | K83: 3 | L83: 3.2 | M83: Нормольно | N83: 1 | O83: лучше
B84: 13103 | C84: Асель Айтбаева | D84: 34929 | E84: Ж | F84: Нет | G84: 2 | H84: 3 | I84: 4 | J84: 2 | K84: 2 | L84: 2.6 | M84: не очень | N84: 0 | O84: хуже
B85: 13113 | C85: Асель Айтбаева | D85: 27.12.2009 | E85: М | F85: Нет | G85: 3 | H85: 5 | I85: 2 | J85: 5 | K85: 4 | L85: 3.8 | M85: Нормольно | N85: 1 | O85: лучше
B86: 13038 | C86: Асель Жанболатқызы | D86: 31.12.1999 | E86: Ж | F86: Нет | G86: 2 | H86: 3 | I86: 2 | J86: 5 | K86: 2 | L86: 2.8 | M86: не очень | N86: 0 | O86: хуже
B87: 13044 | C87: Аяулым Серікқызы | D87: 07.03.1985 | E87: Ж | F87: Нет | G87: 4 | H87: 2 | I87: 5 | J87: 5 | K87: 4 | L87: 4 | M87: Хорошо | N87: 0 | O87: хуже
B88: 13081 | C88: Бауыржан Иманов | D88: 29.09.2008 | E88: М | F88: Да | G88: 2 | H88: 3 | I88: 4 | J88: 5 | K88: 5 | L88: 3.8 | M88: Нормольно | N88: 3 | O88: лучше
B89: 13108 | C89: Бауыржан Кенжебаев | D89: 32221 | E89: М | F89: Да | G89: 4 | H89: 5 | I89: 4 | J89: 4 | K89: 3 | L89: 4 | M89: Хорошо | N89: -1 | O89: хуже
...

Sheet Лист2
A1: 12971 | B1: =COUNTIF(A:A,A1) -> 1
A2: 12972 | B2: =COUNTIF(A:A,A2) -> 1
A3: 12973 | B3: =COUNTIF(A:A,A3) -> 1
A4: 12974 | B4: =COUNTIF(A:A,A4) -> 1
A5: 12975 | B5: =COUNTIF(A:A,A5) -> 1
A6: 12976 | B6: =COUNTIF(A:A,A6) -> 1
A7: 12977 | B7: =COUNTIF(A:A,A7) -> 1
A8: 12978 | B8: =COUNTIF(A:A,A8) -> 1
A9: 12979 | B9: =COUNTIF(A:A,A9) -> 1
A10: 12980 | B10: =COUNTIF(A:A,A10) -> 1
A11: 12981 | B11: =COUNTIF(A:A,A11) -> 1
A12: 12982 | B12: =COUNTIF(A:A,A12) -> 1
... A145: 13115 | B145: =COUNTIF(A:A,A145) -> 1

Sheet Лист3
A2: ФИО | D2: КОЛ-ВО | E2: % | F2: Оценказа1неделю | G2: Оценказа2неделю | H2: Оценказа3неделю | I2: Оценказа4неделю | J2: Оценказа5неделю
A3: Асылзат Мусина | C3: М | D3: =COUNTIF(Успеваемость!E:E,Лист3!C3) -> 72 | E3: =D3/(D3+D4) -> 0.49655172 | F3: =AVERAGEIF(Успеваемость!$E:$E,Лист3!$C$3,Успеваемость!G:G) -> 3.7083333 | G3: =AVERAGEIF(Успеваемость!$E:$E,Лист3!$C$3,Успеваемость!H:H) -> 3.6111111 | H3: =AVERAGEIF(Успеваемость!$E:$E,Лист3!$C$3,Успеваемость!I:I) -> 3.7083333 | I3: =AVERAGEIF(Успеваемость!$E:$E,Лист3!$C$3,Успеваемость!J:J) -> 3.5416667 | J3: =AVERAGEIF(Успеваемость!$E:$E,Лист3!$C$3,Успеваемость!K:K) -> 3.6666667
A4: Ерболат Тулебаев | C4: Ж | D4: =COUNTIF(Успеваемость!E:E,Лист3!C4) -> 73 | E4: =D4/(D4+D3) -> 0.50344828 | F4: =AVERAGEIF(Успеваемость!$E:$E,Лист3!$C$4,Успеваемость!G:G) -> 3.4383562 | G4: =AVERAGEIF(Успеваемость!$E:$E,Лист3!$C$4,Успеваемость!H:H) -> 3.4520548 | H4: =AVERAGEIF(Успеваемость!$E:$E,Лист3!$C$4,Успеваемость!I:I) -> 3.4657534 | I4: =AVERAGEIF(Успеваемость!$E:$E,Лист3!$C$4,Успеваемость!J:J) -> 3.9452055 | J4: =AVERAGEIF(Успеваемость!$E:$E,Лист3!$C$4,Успеваемость!K:K) -> 3.4246575
A5: Данагуль Кенжебаева
A6: Марат Сатыбалдиев | C6: Ранееобучался | D6: КОЛ-ВО | E6: % | F6: Оценказа1неделю | G6: Оценказа2неделю | H6: Оценказа3неделю | I6: Оценказа4неделю | J6: Оценказа5неделю
A7: Сауле Абдукаримова | C7: ДА | D7: =COUNTIF(Успеваемость!F:F,Лист3!C7) -> 75 | E7: =D7/(D7+D8) -> 0.51724138 | F7: =AVERAGEIF(Успеваемость!$F:$F,Лист3!$C$7,Успеваемость!H:H) -> 3.6 | G7: =AVERAGEIF(Успеваемость!$F:$F,Лист3!$C$7,Успеваемость!I:I) -> 3.6933333 | H7: =AVERAGEIF(Успеваемость!$F:$F,Лист3!$C$7,Успеваемость!J:J) -> 3.68 | I7: =AVERAGEIF(Успеваемость!$F:$F,Лист3!$C$7,Успеваемость!K:K) -> 3.56 | J7: =AVERAGEIF(Успеваемость!$F:$F,Лист3!$C$7,Успеваемость!L:L) -> 3.6186667
A8: Бекзат Исакулов | C8: НЕТ | D8: =COUNTIF(Успеваемость!F:F,Лист3!C8) -> 70 | E8: =D8/(D8+D7) -> 0.48275862 | F8: =AVERAGEIF(Успеваемость!$F:$F,Лист3!$C$8,Успеваемость!H:H) -> 3.4571429 | G8: =AVERAGEIF(Успеваемость!$F:$F,Лист3!$C$8,Успеваемость!I:I) -> 3.4714286 | H8: =AVERAGEIF(Успеваемость!$F:$F,Лист3!$C$8,Успеваемость!J:J) -> 3.8142857 | I8: =AVERAGEIF(Успеваемость!$F:$F,Лист3!$C$8,Успеваемость!K:K) -> 3.5285714 | J8: =AVERAGEIF(Успеваемость!$F:$F,Лист3!$C$8,Успеваемость!L:L) -> 3.5714286
A9: Айдана Токаева
A10: Руслан Жунусов | C10: Ранееобучался | D10: КОЛ-ВО | E10: % | F10: Оценказа1неделю | G10: Оценказа2неделю | H10: Оценказа3неделю | I10: Оценказа4неделю | J10: Оценказа5неделю
A11: Алия Садыкова | B11: М | C11: ДА | D11: =COUNTIFS(Успеваемость!F:F,Лист3!C11,Успеваемость!E:E,Лист3!B11) -> 45 | E11: =D11/COUNTA(Лист3!A3:A147) -> 0.31034483 | F11: =AVERAGEIFS(Успеваемость!G:G,Успеваемость!$E:$E,Лист3!$B11,Успеваемость!$F:$F,Лист3!$C11) -> 3.6444444 | G11: =AVERAGEIFS(Успеваемость!H:H,Успеваемость!$E:$E,Лист3!$B11,Успеваемость!$F:$F,Лист3!$C11) -> 3.6666667 | H11: =AVERAGEIFS(Успеваемость!I:I,Успеваемость!$E:$E,Лист3!$B11,Успеваемость!$F:$F,Лист3!$C11) -> 3.7555556 | I11: =AVERAGEIFS(Успеваемость!J:J,Успеваемость!$E:$E,Лист3!$B11,Успеваемость!$F:$F,Лист3!$C11) -> 3.5333333 | J11: =AVERAGEIFS(Успеваемость!K:K,Успеваемость!$E:$E,Лист3!$B11,Успеваемость!$F:$F,Лист3!$C11) -> 3.6666667
A12: Тимур Болатов | B12: М | C12: НЕТ | D12: =COUNTIFS(Успеваемость!F:F,Лист3!C12,Успеваемость!E:E,Лист3!B12) -> 27 | E12: =D12/COUNTA(Лист3!A4:A148) -> 0.1875 | F12: =AVERAGEIFS(Успеваемость!G:G,Успеваемость!$E:$E,Лист3!$B12,Успеваемость!$F:$F,Лист3!$C12) -> 3.8148148 | G12: =AVERAGEIFS(Успеваемость!H:H,Успеваемость!$E:$E,Лист3!$B12,Успеваемость!$F:$F,Лист3!$C12) -> 3.5185185 | H12: =AVERAGEIFS(Успеваемость!I:I,Успеваемость!$E:$E,Лист3!$B12,Успеваемость!$F:$F,Лист3!$C12) -> 3.6296296 | I12: =AVERAGEIFS(Успеваемость!J:J,Успеваемость!$E:$E,Лист3!$B12,Успеваемость!$F:$F,Лист3!$C12) -> 3.5555556 | J12: =AVERAGEIFS(Успеваемость!K:K,Успеваемость!$E:$E,Лист3!$B12,Успеваемость!$F:$F,Лист3!$C12) -> 3.6666667
A13: Камила Утекова | B13: Ж | C13: ДА | D13: =COUNTIFS(Успеваемость!F:F,Лист3!C13,Успеваемость!E:E,Лист3!B13) -> 30 | E13: =D13/COUNTA(Лист3!A5:A149) -> 0.20979021 | F13: =AVERAGEIFS(Успеваемость!G:G,Успеваемость!$E:$E,Лист3!$B13,Успеваемость!$F:$F,Лист3!$C13) -> 3.4333333 | G13: =AVERAGEIFS(Успеваемость!H:H,Успеваемость!$E:$E,Лист3!$B13,Успеваемость!$F:$F,Лист3!$C13) -> 3.5 | H13: =AVERAGEIFS(Успеваемость!I:I,Успеваемость!$E:$E,Лист3!$B13,Успеваемость!$F:$F,Лист3!$C13) -> 3.6 | I13: =AVERAGEIFS(Успеваемость!J:J,Успеваемость!$E:$E,Лист3!$B13,Успеваемость!$F:$F,Лист3!$C13) -> 3.9 | J13: =AVERAGEIFS(Успеваемость!K:K,Успеваемость!$E:$E,Лист3!$B13,Успеваемость!$F:$F,Лист3!$C13) -> 3.4
A14: Даулет Нуржанов | B14: Ж | C14: НЕТ | D14: =COUNTIFS(Успеваемость!F:F,Лист3!C14,Успеваемость!E:E,Лист3!B14) -> 43 | E14: =D14/COUNTA(Лист3!A6:A150) -> 0.3028169 | F14: =AVERAGEIFS(Успеваемость!G:G,Успеваемость!$E:$E,Лист3!$B14,Успеваемость!$F:$F,Лист3!$C14) -> 3.4418605 | G14: =AVERAGEIFS(Успеваемость!H:H,Успеваемость!$E:$E,Лист3!$B14,Успеваемость!$F:$F,Лист3!$C14) -> 3.4186047 | H14: =AVERAGEIFS(Успеваемость!I:I,Успеваемость!$E:$E,Лист3!$B14,Успеваемость!$F:$F,Лист3!$C14) -> 3.372093 | I14: =AVERAGEIFS(Успеваемость!J:J,Успеваемость!$E:$E,Лист3!$B14,Успеваемость!$F:$F,Лист3!$C14) -> 3.9767442 | J14: =AVERAGEIFS(Успеваемость!K:K,Успеваемость!$E:$E,Лист3!$B14,Успеваемость!$F:$F,Лист3!$C14) -> 3.4418605
A15: Данагуль Кенжебаева
A16: Марат Сатыбалдиев
A17: Сауле Абдукаримова
A18: Бекзат Исакулов
A19: Айдана Токаева
A20: Тимур Асанов
A21: Гульнур Оразбаева
A22: Еркебулан Бекбаев
A23: Аида Нургалиева
A24: Руслан Мурзагулов
A25: Мирас Абдуллин
A26: Алма Керимбаева
... A147: Жансая Оразбекова
