Workbook
Name Срез_Город: #N/A
Name Срез_Название_курса: #N/A

Sheet лист 1
A1: Анализ продаж онлайн курсов за 2023 год
A2: ID студента | B2: ФИО студента | C2: Дата рождения | D2: Город | E2: Название курса | F2: Дата покупки | G2: Тип заказа | H2: Стоимость курса, $ | I2: Скидка, % | J2: Оплата за курс, $
A3: 1542 | B3: Дарина Волкова | C3: 32940 | D3: Атырау | E3: =VLOOKUP($A$3,'лист 2'!$A$3:$D$267,2,0) -> AI | F3: =VLOOKUP($A$3,'лист 2'!$A$3:$D$267,3,0) -> 45020 | G3: =VLOOKUP($A$3,'лист 2'!$A$3:$D$267,4,0) -> вебинар | H3: =VLOOKUP($E3,'лист 3'!$A$3:$B$7,2,0) -> 150 | I3: =VLOOKUP($G3,'лист 3'!$E$3:$F$5,2,0) -> 0.1 | J3: =H3-H3*I3 -> 135 | S3: KPI
A4: 1547 | B4: Елена Павлова | C4: 31180 | D4: Атырау | E4: =VLOOKUP(A4,'лист 2'!$A$3:$D$267,2,0) -> AI | F4: =VLOOKUP($A$3,'лист 2'!$A$3:$D$267,3,0) -> 45020 | G4: =VLOOKUP($A$3,'лист 2'!$A$3:$D$267,4,0) -> вебинар | H4: =VLOOKUP($E4,'лист 3'!$A$3:$B$7,2,0) -> 150 | I4: =VLOOKUP($G4,'лист 3'!$E$3:$F$5,2,0) -> 0.1 | J4: =H4-H4*I4 -> 135 | S4: Общая выручка
A5: 1185 | B5: Айдана Абдукаримова | C5: 24253 | D5: Атырау | E5: =VLOOKUP(A5,'лист 2'!$A$3:$D$267,2,0) -> AI | F5: =VLOOKUP($A$3,'лист 2'!$A$3:$D$267,3,0) -> 45020 | G5: =VLOOKUP($A$3,'лист 2'!$A$3:$D$267,4,0) -> вебинар | H5: =VLOOKUP($E5,'лист 3'!$A$3:$B$7,2,0) -> 150 | I5: =VLOOKUP($G5,'лист 3'!$E$3:$F$5,2,0) -> 0.1 | J5: =H5-H5*I5 -> 135 | S5: Кол-во продаж
A6: 1190 | B6: Алишер Бейсенов | C6: 22651 | D6: Астана | E6: =VLOOKUP(A6,'лист 2'!$A$3:$D$267,2,0) -> AI | F6: =VLOOKUP($A$3,'лист 2'!$A$3:$D$267,3,0) -> 45020 | G6: =VLOOKUP($A$3,'лист 2'!$A$3:$D$267,4,0) -> вебинар | H6: =VLOOKUP($E6,'лист 3'!$A$3:$B$7,2,0) -> 150 | I6: =VLOOKUP($G6,'лист 3'!$E$3:$F$5,2,0) -> 0.1 | J6: =H6-H6*I6 -> 135 | S6: Сред.стоимость курса
A7: 1195 | B7: Дильназ Темиргалиева | C7: 26881 | D7: Алматы | E7: =VLOOKUP(A7,'лист 2'!$A$3:$D$267,2,0) -> AI | F7: =VLOOKUP($A$3,'лист 2'!$A$3:$D$267,3,0) -> 45020 | G7: =VLOOKUP($A$3,'лист 2'!$A$3:$D$267,4,0) -> вебинар | H7: =VLOOKUP($E7,'лист 3'!$A$3:$B$7,2,0) -> 150 | I7: =VLOOKUP($G7,'лист 3'!$E$3:$F$5,2,0) -> 0.1 | J7: =H7-H7*I7 -> 135 | S7: Кол-во курсов
A8: 1210 | B8: Нургиса Бекзатова | C8: 30642 | D8: Атырау | E8: =VLOOKUP(A8,'лист 2'!$A$3:$D$267,2,0) -> AI | F8: =VLOOKUP($A$3,'лист 2'!$A$3:$D$267,3,0) -> 45020 | G8: =VLOOKUP($A$3,'лист 2'!$A$3:$D$267,4,0) -> вебинар | H8: =VLOOKUP($E8,'лист 3'!$A$3:$B$7,2,0) -> 150 | I8: =VLOOKUP($G8,'лист 3'!$E$3:$F$5,2,0) -> 0.1 | J8: =H8-H8*I8 -> 135 | S8: Топовый курс
A9: 1215 | B9: Алишер Бекзатов | C9: 32071 | D9: Атырау | E9: =VLOOKUP(A9,'лист 2'!$A$3:$D$267,2,0) -> AI | F9: =VLOOKUP($A$3,'лист 2'!$A$3:$D$267,3,0) -> 45020 | G9: =VLOOKUP($A$3,'лист 2'!$A$3:$D$267,4,0) -> вебинар | H9: =VLOOKUP($E9,'лист 3'!$A$3:$B$7,2,0) -> 150 | I9: =VLOOKUP($G9,'лист 3'!$E$3:$F$5,2,0) -> 0.1 | J9: =H9-H9*I9 -> 135 | S9: Модули
A10: 1290 | B10: Нуржан Абдукаримов | C10: 33148 | D10: Астана | E10: =VLOOKUP(A10,'лист 2'!$A$3:$D$267,2,0) -> AI | F10: =VLOOKUP($A$3,'лист 2'!$A$3:$D$267,3,0) -> 45020 | G10: =VLOOKUP($A$3,'лист 2'!$A$3:$D$267,4,0) -> вебинар | H10: =VLOOKUP($E10,'лист 3'!$A$3:$B$7,2,0) -> 150 | I10: =VLOOKUP($G10,'лист 3'!$E$3:$F$5,2,0) -> 0.1 | J10: =H10-H10*I10 -> 135 | S10: Выручка по курсам
A11: 1220 | B11: Нургиса Темирбекова | C11: 24861 | D11: Алматы | E11: =VLOOKUP(A11,'лист 2'!$A$3:$D$267,2,0) -> AI | F11: =VLOOKUP($A$3,'лист 2'!$A$3:$D$267,3,0) -> 45020 | G11: =VLOOKUP($A$3,'лист 2'!$A$3:$D$267,4,0) -> вебинар | H11: =VLOOKUP($E11,'лист 3'!$A$3:$B$7,2,0) -> 150 | I11: =VLOOKUP($G11,'лист 3'!$E$3:$F$5,2,0) -> 0.1 | J11: =H11-H11*I11 -> 135 | S11: Продажи по городам
A12: 1295 | B12: Айзада Бекболатова | C12: 24805 | D12: Астана | E12: =VLOOKUP(A12,'лист 2'!$A$3:$D$267,2,0) -> AI | F12: =VLOOKUP($A$3,'лист 2'!$A$3:$D$267,3,0) -> 45020 | G12: =VLOOKUP($A$3,'лист 2'!$A$3:$D$267,4,0) -> вебинар | H12: =VLOOKUP($E12,'лист 3'!$A$3:$B$7,2,0) -> 150 | I12: =VLOOKUP($G12,'лист 3'!$E$3:$F$5,2,0) -> 0.1 | J12: =H12-H12*I12 -> 135 | S12: Динамика продаж по месяцам
A13: 1310 | B13: Дамир Абдукаримов | C13: 24814 | D13: Атырау | E13: =VLOOKUP(A13,'лист 2'!$A$3:$D$267,2,0) -> AI | F13: =VLOOKUP($A$3,'лист 2'!$A$3:$D$267,3,0) -> 45020 | G13: =VLOOKUP($A$3,'лист 2'!$A$3:$D$267,4,0) -> вебинар | H13: =VLOOKUP($E13,'лист 3'!$A$3:$B$7,2,0) -> 150 | I13: =VLOOKUP($G13,'лист 3'!$E$3:$F$5,2,0) -> 0.1 | J13: =H13-H13*I13 -> 135 | S13: Средняя цена курса
A14: 1552 | B14: Алексей Попов | C14: 38548 | D14: Астана | E14: =VLOOKUP(A14,'лист 2'!$A$3:$D$267,2,0) -> AI | F14: =VLOOKUP($A$3,'лист 2'!$A$3:$D$267,3,0) -> 45020 | G14: =VLOOKUP($A$3,'лист 2'!$A$3:$D$267,4,0) -> вебинар | H14: =VLOOKUP($E14,'лист 3'!$A$3:$B$7,2,0) -> 150 | I14: =VLOOKUP($G14,'лист 3'!$E$3:$F$5,2,0) -> 0.1 | J14: =H14-H14*I14 -> 135 | S14: Доли выручки в общем объеме
A15: 1200 | B15: Нургиса Бекзатова | C15: 29625 | D15: Атырау | E15: =VLOOKUP(A15,'лист 2'!$A$3:$D$267,2,0) -> AI | F15: =VLOOKUP($A$3,'лист 2'!$A$3:$D$267,3,0) -> 45020 | G15: =VLOOKUP($A$3,'лист 2'!$A$3:$D$267,4,0) -> вебинар | H15: =VLOOKUP($E15,'лист 3'!$A$3:$B$7,2,0) -> 150 | I15: =VLOOKUP($G15,'лист 3'!$E$3:$F$5,2,0) -> 0.1 | J15: =H15-H15*I15 -> 135 | S15: Доли по типу заказа
... A20: 1320 | B20: Дамир Абдукаримов | C20: 22501 | D20: Астана | E20: =VLOOKUP(A20,'лист 2'!$A$3:$D$267,2,0) -> AI | F20: =VLOOKUP($A$3,'лист 2'!$A$3:$D$267,3,0) -> 45020 | G20: =VLOOKUP($A$3,'лист 2'!$A$3:$D$267,4,0) -> вебинар | H20: =VLOOKUP($E20,'лист 3'!$A$3:$B$7,2,0) -> 150 | I20: =VLOOKUP($G20,'лист 3'!$E$3:$F$5,2,0) -> 0.1 | J20: =H20-H20*I20 -> 135 | S20: Дата покупки
A21: 1372 | B21: Сабина Амангельдиева | C21: 22681 | D21: Атырау | E21: =VLOOKUP(A21,'лист 2'!$A$3:$D$267,2,0) -> Excel | F21: =VLOOKUP($A$3,'лист 2'!$A$3:$D$267,3,0) -> 45020 | G21: =VLOOKUP($A$3,'лист 2'!$A$3:$D$267,4,0) -> вебинар | H21: =VLOOKUP($E21,'лист 3'!$A$3:$B$7,2,0) -> 400 | I21: =VLOOKUP($G21,'лист 3'!$E$3:$F$5,2,0) -> 0.1 | J21: =H21-H21*I21 -> 360
A22: 1430 | B22: Ирина Смирнова | C22: 36139 | D22: Атырау | E22: =VLOOKUP(A22,'лист 2'!$A$3:$D$267,2,0) -> Excel | F22: =VLOOKUP($A$3,'лист 2'!$A$3:$D$267,3,0) -> 45020 | G22: =VLOOKUP($A$3,'лист 2'!$A$3:$D$267,4,0) -> вебинар | H22: =VLOOKUP($E22,'лист 3'!$A$3:$B$7,2,0) -> 400 | I22: =VLOOKUP($G22,'лист 3'!$E$3:$F$5,2,0) -> 0.1 | J22: =H22-H22*I22 -> 360
A23: 1448 | B23: Нина Смирнова | C23: 30148 | D23: Атырау | E23: =VLOOKUP(A23,'лист 2'!$A$3:$D$267,2,0) -> Excel | F23: =VLOOKUP($A$3,'лист 2'!$A$3:$D$267,3,0) -> 45020 | G23: =VLOOKUP($A$3,'лист 2'!$A$3:$D$267,4,0) -> вебинар | H23: =VLOOKUP($E23,'лист 3'!$A$3:$B$7,2,0) -> 400 | I23: =VLOOKUP($G23,'лист 3'!$E$3:$F$5,2,0) -> 0.1 | J23: =H23-H23*I23 -> 360
A24: 1435 | B24: Наталья Петрова | C24: 22350 | D24: Атырау | E24: =VLOOKUP(A24,'лист 2'!$A$3:$D$267,2,0) -> Excel | F24: =VLOOKUP($A$3,'лист 2'!$A$3:$D$267,3,0) -> 45020 | G24: =VLOOKUP($A$3,'лист 2'!$A$3:$D$267,4,0) -> вебинар | H24: =VLOOKUP($E24,'лист 3'!$A$3:$B$7,2,0) -> 400 | I24: =VLOOKUP($G24,'лист 3'!$E$3:$F$5,2,0) -> 0.1 | J24: =H24-H24*I24 -> 360
A25: 1453 | B25: Людмила Смирнова | C25: 35954 | D25: Атырау | E25: =VLOOKUP(A25,'лист 2'!$A$3:$D$267,2,0) -> Excel | F25: =VLOOKUP($A$3,'лист 2'!$A$3:$D$267,3,0) -> 45020 | G25: =VLOOKUP($A$3,'лист 2'!$A$3:$D$267,4,0) -> вебинар | H25: =VLOOKUP($E25,'лист 3'!$A$3:$B$7,2,0) -> 400 | I25: =VLOOKUP($G25,'лист 3'!$E$3:$F$5,2,0) -> 0.1 | J25: =H25-H25*I25 -> 360
A26: 1004 | B26: Нуржан Баймуратов | C26: 35024 | D26: Астана | E26: =VLOOKUP(A26,'лист 2'!$A$3:$D$267,2,0) -> Excel | F26: =VLOOKUP($A$3,'лист 2'!$A$3:$D$267,3,0) -> 45020 | G26: =VLOOKUP($A$3,'лист 2'!$A$3:$D$267,4,0) -> вебинар | H26: =VLOOKUP($E26,'лист 3'!$A$3:$B$7,2,0) -> 400 | I26: =VLOOKUP($G26,'лист 3'!$E$3:$F$5,2,0) -> 0.1 | J26: =H26-H26*I26 -> 360
A27: 1009 | B27: Арсен Сабыржанов | C27: 25490 | D27: Астана | E27: =VLOOKUP(A27,'лист 2'!$A$3:$D$267,2,0) -> Excel | F27: =VLOOKUP($A$3,'лист 2'!$A$3:$D$267,3,0) -> 45020 | G27: =VLOOKUP($A$3,'лист 2'!$A$3:$D$267,4,0) -> вебинар | H27: =VLOOKUP($E27,'лист 3'!$A$3:$B$7,2,0) -> 400 | I27: =VLOOKUP($G27,'лист 3'!$E$3:$F$5,2,0) -> 0.1 | J27: =H27-H27*I27 -> 360
A28: 1029 | B28: Аружан Сабыржанова | C28: 31509 | D28: Алматы | E28: =VLOOKUP(A28,'лист 2'!$A$3:$D$267,2,0) -> Excel | F28: =VLOOKUP($A$3,'лист 2'!$A$3:$D$267,3,0) -> 45020 | G28: =VLOOKUP($A$3,'лист 2'!$A$3:$D$267,4,0) -> вебинар | H28: =VLOOKUP($E28,'лист 3'!$A$3:$B$7,2,0) -> 400 | I28: =VLOOKUP($G28,'лист 3'!$E$3:$F$5,2,0) -> 0.1 | J28: =H28-H28*I28 -> 360
A29: 1035 | B29: Аружан Сатыбалдина | C29: 37321 | D29: Астана | E29: =VLOOKUP(A29,'лист 2'!$A$3:$D$267,2,0) -> Excel | F29: =VLOOKUP($A$3,'лист 2'!$A$3:$D$267,3,0) -> 45020 | G29: =VLOOKUP($A$3,'лист 2'!$A$3:$D$267,4,0) -> вебинар | H29: =VLOOKUP($E29,'лист 3'!$A$3:$B$7,2,0) -> 400 | I29: =VLOOKUP($G29,'лист 3'!$E$3:$F$5,2,0) -> 0.1 | J29: =H29-H29*I29 -> 360
A30: 1043 | B30: Данияр Абишев | C30: 28135 | D30: Астана | E30: =VLOOKUP(A30,'лист 2'!$A$3:$D$267,2,0) -> Excel | F30: =VLOOKUP($A$3,'лист 2'!$A$3:$D$267,3,0) -> 45020 | G30: =VLOOKUP($A$3,'лист 2'!$A$3:$D$267,4,0) -> вебинар | H30: =VLOOKUP($E30,'лист 3'!$A$3:$B$7,2,0) -> 400 | I30: =VLOOKUP($G30,'лист 3'!$E$3:$F$5,2,0) -> 0.1 | J30: =H30-H30*I30 -> 360
A31: 1051 | B31: Айдана Ажмуканова | C31: 36760 | D31: Астана | E31: =VLOOKUP(A31,'лист 2'!$A$3:$D$267,2,0) -> Excel | F31: =VLOOKUP($A$3,'лист 2'!$A$3:$D$267,3,0) -> 45020 | G31: =VLOOKUP($A$3,'лист 2'!$A$3:$D$267,4,0) -> вебинар | H31: =VLOOKUP($E31,'лист 3'!$A$3:$B$7,2,0) -> 400 | I31: =VLOOKUP($G31,'лист 3'!$E$3:$F$5,2,0) -> 0.1 | J31: =H31-H31*I31 -> 360
A32: 1054 | B32: Аружан Амангелдиева | C32: 37589 | D32: Алматы | E32: =VLOOKUP(A32,'лист 2'!$A$3:$D$267,2,0) -> Excel | F32: =VLOOKUP($A$3,'лист 2'!$A$3:$D$267,3,0) -> 45020 | G32: =VLOOKUP($A$3,'лист 2'!$A$3:$D$267,4,0) -> вебинар | H32: =VLOOKUP($E32,'лист 3'!$A$3:$B$7,2,0) -> 400 | I32: =VLOOKUP($G32,'лист 3'!$E$3:$F$5,2,0) -> 0.1 | J32: =H32-H32*I32 -> 360
... A267: 1206 | B267: Нургиса Темирбекова | C267: 33249 | D267: Шымкент | E267: =VLOOKUP(A267,'лист 2'!$A$3:$D$267,2,0) -> SQL | F267: =VLOOKUP($A$3,'лист 2'!$A$3:$D$267,3,0) -> 45020 | G267: =VLOOKUP($A$3,'лист 2'!$A$3:$D$267,4,0) -> вебинар | H267: =VLOOKUP($E267,'лист 3'!$A$3:$B$7,2,0) -> 500 | I267: =VLOOKUP($G267,'лист 3'!$E$3:$F$5,2,0) -> 0.1 | J267: =H267-H267*I267 -> 450

Sheet лист 2
A2: ID студента | B2: название курса | C2: дата покупки | D2: тип заказа
A3: 1542 | B3: AI | C3: 45020 | D3: вебинар
A4: 1547 | B4: AI | C4: 45055 | D4: вебинар
A5: 1185 | B5: AI | C5: 44928 | D5: вебинар
A6: 1190 | B6: AI | C6: 44933 | D6: вебинар
A7: 1195 | B7: AI | C7: 45089 | D7: вебинар
A8: 1210 | B8: AI | C8: 45104 | D8: вебинар
A9: 1215 | B9: AI | C9: 45109 | D9: вебинар
A10: 1290 | B10: AI | C10: 45113 | D10: вебинар
A11: 1220 | B11: AI | C11: 45114 | D11: вебинар
A12: 1295 | B12: AI | C12: 45149 | D12: вебинар
A13: 1310 | B13: AI | C13: 45122 | D13: вебинар
A14: 1552 | B14: AI | C14: 45179 | D14: вебинар
... A267: 1206 | B267: SQL | C267: 45283 | D267: инстаграмм

Sheet лист 3
A1: Прайс | E1: Скидки
A2: название курса | B2: стоимость курса, $ | E2: тип заказа | F2: скидка
A3: AI | B3: 150 | E3: инстаграмм | F3: 0.15
A4: Excel | B4: 400 | E4: вебинар | F4: 0.1
A5: Power BI | B5: 600 | E5: без скидки | F5: 0
A6: Python | B6: 500
A7: SQL | B7: 500

Sheet СВОДНЫЕ ТАБ
A2: Выручка по курсам | H2: Общая выручка, $
A3: Название курс | B3: Стоимость курса, $ | H3: 116010 | Q3: KPI
A4: AI | B4: 2700 | Q4: Общая выручка
A5: Excel | B5: 29600 | H5: Кол-во продаж, $ | Q5: Кол-во продаж
A6: Power BI | B6: 60600 | H6: 265 | Q6: Сред.стоимость курса
A7: Python | B7: 12000 | Q7: Кол-во курсов
A8: SQL | B8: 24000 | H8: Сред.стоимость курса, $ | Q8: Топовый курс
A9: Общий итог | B9: 128900 | H9: 486.41509 | Q9: Модули
Q10: Выручка по курсам
H11: Кол-во курсов | Q11: Продажи по городам
H12: AI | Q12: Динамика продаж по месяцам
A13: Продажи по городам | H13: Excel | Q13: Средняя цена курса
A14: город | B14: Сумма по полю ID студента | H14: Power BI | Q14: Доли выручки в общем объеме
A15: Алматы | B15: 109780 | H15: Python | Q15: Доли по типу заказа
A16: Астана | B16: 135145 | H16: SQL | Q16: Разница стоимости курсов
A17: Атырау | B17: 53309 | H17: Общий итог | Q17: Срезы
A18: Караганда | B18: 11668 | Q18: Курс
A19: Костанай | B19: 15001 | H19: Топовый курс | I19: Количество по полю Оплата за курс, $ | Q19: Тип заказа
A20: Оскемен | B20: 5246 | H20: Power BI | I20: 101 | Q20: Дата покупки
A21: Шымкент | B21: 21347 | H21: Общий итог | I21: 101
A22: Общий итог | B22: 351496
A27: Название курс | B27: Стоимость курса, $
A28: 45020 | B28: 128900
A29: Общий итог | B29: 128900
A32: Средняя цена курса
A33: курс | B33: Среднее Стоимость курса, $
A34: AI | B34: 150
A35: Excel | B35: 400
A36: Power BI | B36: 600
A37: Python | B37: 500
A38: SQL | B38: 500
A39: Общий итог | B39: 486.41509
A42: Доли выручки в общем объеме
A43: курс | B43: КоличествоСтоимость курса, $
A44: AI | B44: 0.067924528
A45: Excel | B45: 0.27924528
A46: Power BI | B46: 0.38113208
A47: Python | B47: 0.090566038
A48: SQL | B48: 0.18113208
A49: Общий итог | B49: 1
...

Sheet ДАШ
A1: АНАЛИЗ ПРОДАЖ ОНЛАЙН КУРСОВ 2023
P13: =GETPIVOTDATA("Оплата за курс, $",'СВОДНЫЕ ТАБ'!$H$2) -> 116010
